Workbook

Sheet Cover
A1: HCA HEALTHCARE, INC. (HCA)
A7: Leveraged Buyout (LBO) Analysis | Hypothetical Private Equity Acquisition | Portfolio Model | April 2026
B10: KEY MODEL OUTPUTS
B11: Entry EV ($M) | D11: =Assumptions!B8 -> 164220
B12: Entry EV/EBITDA | D12: =Assumptions!B9 -> 11.5
B13: Total Equity Invested ($M) | D13: ='Sources & Uses'!B18 -> 75541.2
B14: Exit EV ($M) | D14: =Returns!B6 -> 237641.04
B15: IRR (5-Year Hold) | D15: =Returns!B15 -> 0.20616336
B16: MOIC (5-Year Hold) | D16: =Returns!B16 -> 2.5528816
B17: Exit EV/EBITDA | D17: =Assumptions!B22 -> 0.085
B32: Hypothetical LBO for portfolio purposes only. Not investment advice. HCA went public in 2011 after a 2006 LBO. This model simulates a re-privatization scenario. Historical figures from HCA 10-K filings.
B34: Blue | C34: Hardcoded input
B35: Black | C35: Formula / calculated
B36: Green | C36: Cross-sheet ref

Sheet Assumptions
A1: LBO ASSUMPTIONS — HCA Healthcare (HCA)
A3: A | Entry Assumptions (Acquisition)
A4: Transaction Date | B4: April 2026 | C4: Hypothetical entry date
A5: LTM Revenue at Entry ($M) | B5: 66252 | C5: Source: HCA FY2025 estimated revenue (consensus)
A6: LTM EBITDA at Entry ($M) | B6: 14280 | C6: Source: HCA FY2025 estimated EBITDA (consensus); ~21.6% margin
A7: LTM EBITDA Margin (%) | B7: =B6/B5 -> 0.21554066 | C7: Calculated
A8: Entry Enterprise Value ($M) | B8: =B6*B9 -> 164220 | C8: EV = EBITDA × Entry Multiple
A9: Entry EV/EBITDA Multiple | B9: 11.5 | C9: Peer group trading at 10-12x; slight control premium applied
A10: (-) Net Debt at Entry ($M) | B10: 36500 | C10: Source: HCA FY2025E Net Debt (Total Debt less Cash)
A11: Entry Equity Value ($M) | B11: =B8-B10 -> 127720 | C11: EV less Net Debt
A12: Shares Outstanding (M) | B12: 262 | C12: Source: HCA FY2025 diluted share count
A13: Implied Entry Price/Share ($) | B13: =B11/B12*1000 -> 487480.92 | C13: Entry Equity Value ÷ Shares
A15: B | Capital Structure at Entry (Sources of Funds)
A16: Senior Secured Loan (Term Loan B) | B16: 0.35 | C16: Typical LBO leverage: 3.5–4.5x EBITDA for healthcare
A17: Senior Secured Notes | B17: 0.1 | C17: High-yield secured debt tranche
A18: Senior Unsecured Notes | B18: 0.1 | C18: Subordinated to secured tranches
A19: Total Debt (% of EV) | B19: =B16+B17+B18 -> 0.55 | C19: Sum of debt tranches
A20: Sponsor Equity (% of EV) | B20: =1-B19 -> 0.45 | C20: 1 - Total Debt %
A21: Effective Interest Rate — TLB | B21: 0.08 | C21: SOFR + 300bps spread; current SOFR ~4.5%
A22: Effective Interest Rate — Sec Notes | B22: 0.085 | C22: Fixed rate high-yield
A23: Effective Interest Rate — Unsec | B23: 0.095 | C23: Fixed rate; junior ranking
A24: Mandatory Amortization (TLB) | B24: 0.01 | C24: 1% per annum on original balance
A25: Cash Sweep (%) | B25: 0.5 | C25: 50% of excess FCF applied to debt repayment
A27: C | Exit Assumptions
A28: Hold Period (Years) | B28: 5 | C28: Standard PE hold period
A29: Exit EV/EBITDA Multiple | B29: 12 | C29: Slight premium to entry; assumes improved credit profile
A30: Transaction Fees at Entry (% EV) | B30: 0.02 | C30: M&A advisory, financing, legal fees
A31: Transaction Fees at Exit (% EV) | B31: 0.015 | C31: Sell-side advisory and closing costs
A33: D | Operating Projection Assumptions (Post-LBO)
A34: Revenue Growth (FY2026E) | B34: 0.06 | C34: Strong same-store growth + bed expansion
A35: Revenue Growth (FY2027E) | B35: 0.055 | C35: Moderating growth as capacity fills
A36: Revenue Growth (FY2028E) | B36: 0.05
A37: Revenue Growth (FY2029E) | B37: 0.05
A38: Revenue Growth (FY2030E) | B38: 0.045 | C38: Exit year
A39: EBITDA Margin (FY2026E) | B39: 0.22 | C39: PE ownership drives operational efficiency
A40: EBITDA Margin (FY2027E) | B40: 0.225 | C40: Labor cost optimization, vendor renegotiation
A41: EBITDA Margin (FY2028E) | B41: 0.228
A42: EBITDA Margin (FY2029E) | B42: 0.23
A43: EBITDA Margin (FY2030E) | B43: 0.232 | C43: Exit year
A44: D&A (% Revenue) | B44: 0.04 | C44: Depreciation on existing PP&E + new capex
...

Sheet Sources & Uses
A1: SOURCES & USES OF FUNDS — HCA Healthcare LBO ($M)
A3: USES OF FUNDS
B4: Amount ($M) | C4: % of Total Uses | D4: Notes
A5: Purchase of Equity (Entry EV less Assumed Debt) | B5: =Assumptions!B11 -> 127720 | C5: =IF(B9=0,0,B5/B9) -> 0.75508464
A6: Refinance / Assume Existing Debt | B6: =Assumptions!B10 -> 36500 | C6: =IF(B9=0,0,B6/B9) -> 0.21578914 | D6: Replace existing HCA debt with LBO financing
A7: Transaction Fees & Expenses | B7: =Assumptions!B8*Assumptions!B30 -> 3284.4 | C7: =IF(B9=0,0,B7/B9) -> 0.019417476 | D7: Advisory, financing, legal
A8: OID / Financing Fees (Debt) | B8: =Assumptions!B8*0.01 -> 1642.2 | C8: =IF(B9=0,0,B8/B9) -> 0.0097087379 | D8: ~1% of EV; amortized over debt life
A9: Total Uses | B9: =SUM(B5:B8) -> 169146.6 | C9: =B9/B9 -> 1
A11: SOURCES OF FUNDS
B12: Amount ($M) | C12: % of Total Sources | D12: Notes
A13: Senior Secured Term Loan B (TLB) | B13: =Assumptions!B8*Assumptions!B16 -> 57477 | C13: =B13/B9 -> 0.33980583
A14: Senior Secured Notes | B14: =Assumptions!B8*Assumptions!B17 -> 16422 | C14: =B14/B9 -> 0.097087379
A15: Senior Unsecured Notes | B15: =Assumptions!B8*Assumptions!B18 -> 16422 | C15: =B15/B9 -> 0.097087379
A16: Total Debt | B16: =SUM(B13:B15) -> 90321 | C16: =B16/B9 -> 0.53398058
A17: Rolled Management Equity | B17: =Assumptions!B8*0.02 -> 3284.4 | C17: =B17/B9 -> 0.019417476 | D17: ~2% of EV; mgmt rollover
A18: Sponsor Equity | B18: =B9-B16-B17 -> 75541.2 | C18: =B18/B9 -> 0.44660194 | D18: Residual equity check
A19: Total Sources | B19: =SUM(B13:B15)+B17+B18 -> 169146.6
A20: Check: Sources = Uses? | B20: =IF(ABS(B19-B9)<1,"Balanced","ERROR") -> Balanced
A22: Key Leverage Statistics at Entry
A23: Total Debt / Entry EBITDA | B23: =B16/Assumptions!B6 -> 6.325
A24: Senior Secured Debt / EBITDA | B24: =(B13+B14)/Assumptions!B6 -> 5.175
A25: Net Debt / EBITDA | B25: =(B16-Assumptions!B8*0.02)/Assumptions!B6 -> 6.095
A26: Total Debt / Entry EV | B26: =B16/Assumptions!B8 -> 0.55
A27: Sponsor Equity / Entry EV | B27: =(B17+B18)/Assumptions!B8 -> 0.48

Sheet Operating Model
A1: HCA HEALTHCARE — Post-LBO Operating Model ($M)
A3: Figures in $M unless noted | B3: FY2025 (Entry) | C3: FY2026E | D3: FY2027E | E3: FY2028E | F3: FY2029E | G3: FY2030E (Exit) | H3: Notes
A4: INCOME STATEMENT
A5: Revenue | B5: 66252 | C5: =B5*(1+Assumptions!$B$34) -> 70227.12 | D5: =C5*(1+Assumptions!$B$35) -> 74089.612 | E5: =D5*(1+Assumptions!$B$36) -> 77794.092 | F5: =E5*(1+Assumptions!$B$37) -> 81683.797 | G5: =F5*(1+Assumptions!$B$38) -> 85359.568 | H5: Source: HCA FY2025E consensus; FY2026+ per Assumptions D
A6: EBITDA | B6: 14280 | C6: =C5*Assumptions!$B$39 -> 15449.966 | D6: =D5*Assumptions!$B$40 -> 16670.163 | E6: =E5*Assumptions!$B$41 -> 17737.053 | F6: =F5*Assumptions!$B$42 -> 18787.273 | G6: =G5*Assumptions!$B$43 -> 19803.42 | H6: Source: HCA FY2025E consensus; FY2026+ per Assumptions D
A7: EBITDA Margin % | B7: =B6/B5 -> 0.21554066 | C7: =C6/C5 -> 0.22 | D7: =D6/D5 -> 0.225 | E7: =E6/E5 -> 0.228 | F7: =F6/F5 -> 0.23 | G7: =G6/G5 -> 0.232
A8: (-) Depreciation & Amortization | B8: 2650 | C8: =C5*Assumptions!$B$44 -> 2809.0848 | D8: =D5*Assumptions!$B$44 -> 2963.5845 | E8: =E5*Assumptions!$B$44 -> 3111.7637 | F8: =F5*Assumptions!$B$44 -> 3267.3519 | G8: =G5*Assumptions!$B$44 -> 3414.3827 | H8: Source: HCA FY2025E; projected at 4.0% of revenue
A9: EBIT (Operating Income) | B9: =B6-B8 -> 11630 | C9: =C6-C8 -> 12640.882 | D9: =D6-D8 -> 13706.578 | E9: =E6-E8 -> 14625.289 | F9: =F6-F8 -> 15519.921 | G9: =G6-G8 -> 16389.037
A10: EBIT Margin % | B10: =B9/B5 -> 0.17554187 | C10: =C9/C5 -> 0.18 | D10: =D9/D5 -> 0.185 | E10: =E9/E5 -> 0.188 | F10: =F9/F5 -> 0.19 | G10: =G9/G5 -> 0.192
A12: DEBT SCHEDULE — Interest Expense & Amortization
A13: Balance / Amount ($M) | B13: FY2025 (Entry) | C13: FY2026E | D13: FY2027E | E13: FY2028E | F13: FY2029E | G13: FY2030E (Exit)
A14: TLB Balance (Beginning) | B14: ='Sources & Uses'!B13 -> 57477 | C14: =B15 -> 574.77 | D14: =C15 -> 574.77 | E14: =D15 -> 574.77 | F14: =E15 -> 574.77 | G14: =F15 -> 574.77
A15: TLB Mandatory Amortization (1%) | B15: ='Sources & Uses'!$B$13*Assumptions!$B$24 -> 574.77 | C15: ='Sources & Uses'!$B$13*Assumptions!$B$24 -> 574.77 | D15: ='Sources & Uses'!$B$13*Assumptions!$B$24 -> 574.77 | E15: ='Sources & Uses'!$B$13*Assumptions!$B$24 -> 574.77 | F15: ='Sources & Uses'!$B$13*Assumptions!$B$24 -> 574.77 | G15: ='Sources & Uses'!$B$13*Assumptions!$B$24 -> 574.77
A16: TLB Cash Sweep (50% Excess FCF) | B16: =0 -> 0 | C16: =MAX(0,C36*Assumptions!$B$25) -> 2381.3082 | D16: =MAX(0,D36*Assumptions!$B$25) -> 2727.8979 | E16: =MAX(0,E36*Assumptions!$B$25) -> 3022.3051 | F16: =MAX(0,F36*Assumptions!$B$25) -> 3303.7715 | G16: =MAX(0,G36*Assumptions!$B$25) -> 3580.4668
A17: TLB Balance (Ending) | B17: =MAX(0,B14-B15-B16) -> 56902.23 | C17: =MAX(0,C14-C15-C16) -> 0 | D17: =MAX(0,D14-D15-D16) -> 0 | E17: =MAX(0,E14-E15-E16) -> 0 | F17: =MAX(0,F14-F15-F16) -> 0 | G17: =MAX(0,G14-G15-G16) -> 0
A19: Senior Secured Notes Balance | B19: ='Sources & Uses'!$B$14 -> 16422 | C19: ='Sources & Uses'!$B$14 -> 16422 | D19: ='Sources & Uses'!$B$14 -> 16422 | E19: ='Sources & Uses'!$B$14 -> 16422 | F19: ='Sources & Uses'!$B$14 -> 16422 | G19: ='Sources & Uses'!$B$14 -> 16422
A20: Senior Unsecured Notes Balance | B20: ='Sources & Uses'!$B$15 -> 16422 | C20: ='Sources & Uses'!$B$15 -> 16422 | D20: ='Sources & Uses'!$B$15 -> 16422 | E20: ='Sources & Uses'!$B$15 -> 16422 | F20: ='Sources & Uses'!$B$15 -> 16422 | G20: ='Sources & Uses'!$B$15 -> 16422
A21: Total Debt (Ending) | B21: =B17+B19+B20 -> 89746.23 | C21: =C17+C19+C20 -> 32844 | D21: =D17+D19+D20 -> 32844 | E21: =E17+E19+E20 -> 32844 | F21: =F17+F19+F20 -> 32844 | G21: =G17+G19+G20 -> 32844
A23: Interest Expense by Tranche
A24: TLB Interest | B24: =B14*Assumptions!$B$21 -> 4598.16 | C24: =C14*Assumptions!$B$21 -> 45.9816 | D24: =D14*Assumptions!$B$21 -> 45.9816 | E24: =E14*Assumptions!$B$21 -> 45.9816 | F24: =F14*Assumptions!$B$21 -> 45.9816 | G24: =G14*Assumptions!$B$21 -> 45.9816 | H24: Avg balance × rate
A25: Secured Notes Interest | B25: ='Sources & Uses'!$B$14*Assumptions!$B$22 -> 1395.87 | C25: ='Sources & Uses'!$B$14*Assumptions!$B$22 -> 1395.87 | D25: ='Sources & Uses'!$B$14*Assumptions!$B$22 -> 1395.87 | E25: ='Sources & Uses'!$B$14*Assumptions!$B$22 -> 1395.87 | F25: ='Sources & Uses'!$B$14*Assumptions!$B$22 -> 1395.87 | G25: ='Sources & Uses'!$B$14*Assumptions!$B$22 -> 1395.87 | H25: Fixed rate × original balance
A26: Unsecured Notes Interest | B26: ='Sources & Uses'!$B$15*Assumptions!$B$23 -> 1560.09 | C26: ='Sources & Uses'!$B$15*Assumptions!$B$23 -> 1560.09 | D26: ='Sources & Uses'!$B$15*Assumptions!$B$23 -> 1560.09 | E26: ='Sources & Uses'!$B$15*Assumptions!$B$23 -> 1560.09 | F26: ='Sources & Uses'!$B$15*Assumptions!$B$23 -> 1560.09 | G26: ='Sources & Uses'!$B$15*Assumptions!$B$23 -> 1560.09 | H26: Fixed rate × original balance
A27: Total Interest Expense | B27: =B24+B25+B26 -> 7554.12 | C27: =C24+C25+C26 -> 3001.9416 | D27: =D24+D25+D26 -> 3001.9416 | E27: =E24+E25+E26 -> 3001.9416 | F27: =F24+F25+F26 -> 3001.9416 | G27: =G24+G25+G26 -> 3001.9416
A29: FREE CASH FLOW (Used for Debt Repayment)
A30: EBITDA | B30: =B6 -> 14280 | C30: =C6 -> 15449.966 | D30: =D6 -> 16670.163 | E30: =E6 -> 17737.053 | F30: =F6 -> 18787.273 | G30: =G6 -> 19803.42
A31: (-) Cash Interest Expense | B31: =B27 -> 7554.12 | C31: =C27 -> 3001.9416 | D31: =D27 -> 3001.9416 | E31: =E27 -> 3001.9416 | F31: =F27 -> 3001.9416 | G31: =G27 -> 3001.9416
A32: (-) Mandatory TLB Amortization | B32: =B15 -> 574.77 | C32: =C15 -> 574.77 | D32: =D15 -> 574.77 | E32: =E15 -> 574.77 | F32: =F15 -> 574.77 | G32: =G15 -> 574.77
A33: (-) Capital Expenditures | B33: =B5*Assumptions!$B$45 -> 4306.38 | C33: =C5*Assumptions!$B$45 -> 4564.7628 | D33: =D5*Assumptions!$B$45 -> 4815.8248 | E33: =E5*Assumptions!$B$45 -> 5056.616 | F33: =F5*Assumptions!$B$45 -> 5309.4468 | G33: =G5*Assumptions!$B$45 -> 5548.3719
A34: (-) Cash Taxes [= (EBIT − Interest) × Tax Rate] | B34: =MAX(0,(B9-B27)*Assumptions!$B$47) -> 1059.7288 | C34: =MAX(0,(C9-C27)*Assumptions!$B$47) -> 2506.1244 | D34: =MAX(0,(D9-D27)*Assumptions!$B$47) -> 2783.2055 | E34: =MAX(0,(E9-E27)*Assumptions!$B$47) -> 3022.0704 | F34: =MAX(0,(F9-F27)*Assumptions!$B$47) -> 3254.6747 | G34: =MAX(0,(G9-G27)*Assumptions!$B$47) -> 3480.6448
A35: (-) Change in Net Working Capital | B35: 0 | C35: =(C5-B5)*Assumptions!$B$46 -> 39.7512 | D35: =(D5-C5)*Assumptions!$B$46 -> 38.624916 | E35: =(E5-D5)*Assumptions!$B$46 -> 37.044806 | F35: =(F5-E5)*Assumptions!$B$46 -> 38.897046 | G35: =(G5-F5)*Assumptions!$B$46 -> 36.757709
A36: Levered Free Cash Flow (Available for Debt Sweep) | B36: =B30-B31-B32-B33-B34-B35 -> 785.0012 | C36: =C30-C31-C32-C33-C34-C35 -> 4762.6164 | D36: =D30-D31-D32-D33-D34-D35 -> 5455.7958 | E36: =E30-E31-E32-E33-E34-E35 -> 6044.6102 | F36: =F30-F31-F32-F33-F34-F35 -> 6607.5431 | G36: =G30-G31-G32-G33-G34-G35 -> 7160.9337
A37: LFCF Margin % | B37: =B36/B5 -> 0.011848717 | C37: =C36/C5 -> 0.067817339 | D37: =D36/D5 -> 0.073637798 | E37: =E36/E5 -> 0.077700119 | F37: =F36/F5 -> 0.080891723 | G37: =G36/G5 -> 0.083891401

Sheet Returns
A1: RETURNS ANALYSIS — HCA Healthcare LBO ($M)
A3: Exit Valuation (5-Year Hold — FY2030)
A4: Exit Year EBITDA ($M) | B4: ='Operating Model'!G6 -> 19803.42
A5: Exit EV/EBITDA Multiple | B5: =Assumptions!B29 -> 12
A6: Exit Enterprise Value ($M) | B6: =B4*B5 -> 237641.04
A7: (-) Exit Transaction Fees | B7: =B6*Assumptions!B31 -> 3564.6155
A8: (-) Net Debt at Exit ($M) | B8: ='Operating Model'!G21 -> 32844
A9: Exit Equity Value ($M) | B9: =B6-B7-B8 -> 201232.42
A11: Sponsor Returns
A12: Total Equity Invested at Entry ($M) | B12: ='Sources & Uses'!B18 -> 75541.2
A13: Sponsor % of Exit Equity | B13: =('Sources & Uses'!B18)/('Sources & Uses'!B18+'Sources & Uses'!B17) -> 0.95833333
A14: Sponsor Proceeds at Exit ($M) | B14: =B9*B13 -> 192847.74
A15: ➤ IRR [=(MOIC^(1/n)) − 1] | B15: =(B14/B12)^(1/Assumptions!B28)-1 -> 0.20616336
A16: ➤ MOIC (Money-on-Invested-Capital) | B16: =B14/B12 -> 2.5528816
A17: Hold Period (Years) | B17: =Assumptions!B28 -> 5
A19: Sensitivity — MOIC | Entry Multiple (rows) × Exit Multiple (cols)
A20: Entry EV/EBITDA → Exit EV/EBITDA ↓ | B20: 10 | C20: 10.5 | D20: 11 | E20: 11.5 | F20: 12 | G20: 12.5
A21: 10 | B21: =MAX(0,('Operating Model'!$G$6*10-'Operating Model'!$G$21)/(('Sources & Uses'!$B$18/Assumptions!$B$8)*10*Assumptions!$B$6)) -> 2.5147698 | C21: =MAX(0,('Operating Model'!$G$6*10-'Operating Model'!$G$21)/(('Sources & Uses'!$B$18/Assumptions!$B$8)*10.5*Assumptions!$B$6)) -> 2.3950188 | D21: =MAX(0,('Operating Model'!$G$6*10-'Operating Model'!$G$21)/(('Sources & Uses'!$B$18/Assumptions!$B$8)*11*Assumptions!$B$6)) -> 2.2861543 | E21: =MAX(0,('Operating Model'!$G$6*10-'Operating Model'!$G$21)/(('Sources & Uses'!$B$18/Assumptions!$B$8)*11.5*Assumptions!$B$6)) -> 2.1867563 | F21: =MAX(0,('Operating Model'!$G$6*10-'Operating Model'!$G$21)/(('Sources & Uses'!$B$18/Assumptions!$B$8)*12*Assumptions!$B$6)) -> 2.0956415 | G21: =MAX(0,('Operating Model'!$G$6*10-'Operating Model'!$G$21)/(('Sources & Uses'!$B$18/Assumptions!$B$8)*12.5*Assumptions!$B$6)) -> 2.0118158
A22: 11 | B22: =MAX(0,('Operating Model'!$G$6*11-'Operating Model'!$G$21)/(('Sources & Uses'!$B$18/Assumptions!$B$8)*10*Assumptions!$B$6)) -> 2.8162468 | C22: =MAX(0,('Operating Model'!$G$6*11-'Operating Model'!$G$21)/(('Sources & Uses'!$B$18/Assumptions!$B$8)*10.5*Assumptions!$B$6)) -> 2.6821398 | D22: =MAX(0,('Operating Model'!$G$6*11-'Operating Model'!$G$21)/(('Sources & Uses'!$B$18/Assumptions!$B$8)*11*Assumptions!$B$6)) -> 2.5602243 | E22: =MAX(0,('Operating Model'!$G$6*11-'Operating Model'!$G$21)/(('Sources & Uses'!$B$18/Assumptions!$B$8)*11.5*Assumptions!$B$6)) -> 2.4489102 | F22: =MAX(0,('Operating Model'!$G$6*11-'Operating Model'!$G$21)/(('Sources & Uses'!$B$18/Assumptions!$B$8)*12*Assumptions!$B$6)) -> 2.3468723 | G22: =MAX(0,('Operating Model'!$G$6*11-'Operating Model'!$G$21)/(('Sources & Uses'!$B$18/Assumptions!$B$8)*12.5*Assumptions!$B$6)) -> 2.2529974
A23: 12 | B23: =MAX(0,('Operating Model'!$G$6*12-'Operating Model'!$G$21)/(('Sources & Uses'!$B$18/Assumptions!$B$8)*10*Assumptions!$B$6)) -> 3.1177237 | C23: =MAX(0,('Operating Model'!$G$6*12-'Operating Model'!$G$21)/(('Sources & Uses'!$B$18/Assumptions!$B$8)*10.5*Assumptions!$B$6)) -> 2.9692607 | D23: =MAX(0,('Operating Model'!$G$6*12-'Operating Model'!$G$21)/(('Sources & Uses'!$B$18/Assumptions!$B$8)*11*Assumptions!$B$6)) -> 2.8342943 | E23: =MAX(0,('Operating Model'!$G$6*12-'Operating Model'!$G$21)/(('Sources & Uses'!$B$18/Assumptions!$B$8)*11.5*Assumptions!$B$6)) -> 2.7110641 | F23: =MAX(0,('Operating Model'!$G$6*12-'Operating Model'!$G$21)/(('Sources & Uses'!$B$18/Assumptions!$B$8)*12*Assumptions!$B$6)) -> 2.5981031 | G23: =MAX(0,('Operating Model'!$G$6*12-'Operating Model'!$G$21)/(('Sources & Uses'!$B$18/Assumptions!$B$8)*12.5*Assumptions!$B$6)) -> 2.494179
A24: 13 | B24: =MAX(0,('Operating Model'!$G$6*13-'Operating Model'!$G$21)/(('Sources & Uses'!$B$18/Assumptions!$B$8)*10*Assumptions!$B$6)) -> 3.4192007 | C24: =MAX(0,('Operating Model'!$G$6*13-'Operating Model'!$G$21)/(('Sources & Uses'!$B$18/Assumptions!$B$8)*10.5*Assumptions!$B$6)) -> 3.2563816 | D24: =MAX(0,('Operating Model'!$G$6*13-'Operating Model'!$G$21)/(('Sources & Uses'!$B$18/Assumptions!$B$8)*11*Assumptions!$B$6)) -> 3.1083643 | E24: =MAX(0,('Operating Model'!$G$6*13-'Operating Model'!$G$21)/(('Sources & Uses'!$B$18/Assumptions!$B$8)*11.5*Assumptions!$B$6)) -> 2.973218 | F24: =MAX(0,('Operating Model'!$G$6*13-'Operating Model'!$G$21)/(('Sources & Uses'!$B$18/Assumptions!$B$8)*12*Assumptions!$B$6)) -> 2.8493339 | G24: =MAX(0,('Operating Model'!$G$6*13-'Operating Model'!$G$21)/(('Sources & Uses'!$B$18/Assumptions!$B$8)*12.5*Assumptions!$B$6)) -> 2.7353606
A25: 14 | B25: =MAX(0,('Operating Model'!$G$6*14-'Operating Model'!$G$21)/(('Sources & Uses'!$B$18/Assumptions!$B$8)*10*Assumptions!$B$6)) -> 3.7206777 | C25: =MAX(0,('Operating Model'!$G$6*14-'Operating Model'!$G$21)/(('Sources & Uses'!$B$18/Assumptions!$B$8)*10.5*Assumptions!$B$6)) -> 3.5435026 | D25: =MAX(0,('Operating Model'!$G$6*14-'Operating Model'!$G$21)/(('Sources & Uses'!$B$18/Assumptions!$B$8)*11*Assumptions!$B$6)) -> 3.3824343 | E25: =MAX(0,('Operating Model'!$G$6*14-'Operating Model'!$G$21)/(('Sources & Uses'!$B$18/Assumptions!$B$8)*11.5*Assumptions!$B$6)) -> 3.2353719 | F25: =MAX(0,('Operating Model'!$G$6*14-'Operating Model'!$G$21)/(('Sources & Uses'!$B$18/Assumptions!$B$8)*12*Assumptions!$B$6)) -> 3.1005647 | G25: =MAX(0,('Operating Model'!$G$6*14-'Operating Model'!$G$21)/(('Sources & Uses'!$B$18/Assumptions!$B$8)*12.5*Assumptions!$B$6)) -> 2.9765421
A27: Sensitivity — IRR | Entry Multiple (rows) × Exit Multiple (cols)
A28: Entry EV/EBITDA → Exit EV/EBITDA ↓ | B28: 10 | C28: 10.5 | D28: 11 | E28: 11.5 | F28: 12 | G28: 12.5
A29: 10 | B29: =IF(MAX(0.001,('Operating Model'!$G$6*10-'Operating Model'!$G$21)/(('Sources & Uses'!$B$18/Assumptions!$B$8)*10*Assumptions!$B$6))>0,MAX(0.001,('Operating Model'!$G$6*10-'Operating Model'!$G$21)/(('Sources & Uses'!$B$18/Assumptions!$B$8)*10*Assumptions!$B$6))^(1/Assumptions!$B$28)-1,"N/A") -> 0.20254032 | C29: =IF(MAX(0.001,('Operating Model'!$G$6*10-'Operating Model'!$G$21)/(('Sources & Uses'!$B$18/Assumptions!$B$8)*10.5*Assumptions!$B$6))>0,MAX(0.001,('Operating Model'!$G$6*10-'Operating Model'!$G$21)/(('Sources & Uses'!$B$18/Assumptions!$B$8)*10.5*Assumptions!$B$6))^(1/Assumptions!$B$28)-1,"N/A") -> 0.19086296 | D29: =IF(MAX(0.001,('Operating Model'!$G$6*10-'Operating Model'!$G$21)/(('Sources & Uses'!$B$18/Assumptions!$B$8)*11*Assumptions!$B$6))>0,MAX(0.001,('Operating Model'!$G$6*10-'Operating Model'!$G$21)/(('Sources & Uses'!$B$18/Assumptions!$B$8)*11*Assumptions!$B$6))^(1/Assumptions!$B$28)-1,"N/A") -> 0.17983455 | E29: =IF(MAX(0.001,('Operating Model'!$G$6*10-'Operating Model'!$G$21)/(('Sources & Uses'!$B$18/Assumptions!$B$8)*11.5*Assumptions!$B$6))>0,MAX(0.001,('Operating Model'!$G$6*10-'Operating Model'!$G$21)/(('Sources & Uses'!$B$18/Assumptions!$B$8)*11.5*Assumptions!$B$6))^(1/Assumptions!$B$28)-1,"N/A") -> 0.16939189 | F29: =IF(MAX(0.001,('Operating Model'!$G$6*10-'Operating Model'!$G$21)/(('Sources & Uses'!$B$18/Assumptions!$B$8)*12*Assumptions!$B$6))>0,MAX(0.001,('Operating Model'!$G$6*10-'Operating Model'!$G$21)/(('Sources & Uses'!$B$18/Assumptions!$B$8)*12*Assumptions!$B$6))^(1/Assumptions!$B$28)-1,"N/A") -> 0.15948036 | G29: =IF(MAX(0.001,('Operating Model'!$G$6*10-'Operating Model'!$G$21)/(('Sources & Uses'!$B$18/Assumptions!$B$8)*12.5*Assumptions!$B$6))>0,MAX(0.001,('Operating Model'!$G$6*10-'Operating Model'!$G$21)/(('Sources & Uses'!$B$18/Assumptions!$B$8)*12.5*Assumptions!$B$6))^(1/Assumptions!$B$28)-1,"N/A") -> 0.15005244
A30: 11 | B30: =IF(MAX(0.001,('Operating Model'!$G$6*11-'Operating Model'!$G$21)/(('Sources & Uses'!$B$18/Assumptions!$B$8)*10*Assumptions!$B$6))>0,MAX(0.001,('Operating Model'!$G$6*11-'Operating Model'!$G$21)/(('Sources & Uses'!$B$18/Assumptions!$B$8)*10*Assumptions!$B$6))^(1/Assumptions!$B$28)-1,"N/A") -> 0.23008222 | C30: =IF(MAX(0.001,('Operating Model'!$G$6*11-'Operating Model'!$G$21)/(('Sources & Uses'!$B$18/Assumptions!$B$8)*10.5*Assumptions!$B$6))>0,MAX(0.001,('Operating Model'!$G$6*11-'Operating Model'!$G$21)/(('Sources & Uses'!$B$18/Assumptions!$B$8)*10.5*Assumptions!$B$6))^(1/Assumptions!$B$28)-1,"N/A") -> 0.21813741 | D30: =IF(MAX(0.001,('Operating Model'!$G$6*11-'Operating Model'!$G$21)/(('Sources & Uses'!$B$18/Assumptions!$B$8)*11*Assumptions!$B$6))>0,MAX(0.001,('Operating Model'!$G$6*11-'Operating Model'!$G$21)/(('Sources & Uses'!$B$18/Assumptions!$B$8)*11*Assumptions!$B$6))^(1/Assumptions!$B$28)-1,"N/A") -> 0.20685642 | E30: =IF(MAX(0.001,('Operating Model'!$G$6*11-'Operating Model'!$G$21)/(('Sources & Uses'!$B$18/Assumptions!$B$8)*11.5*Assumptions!$B$6))>0,MAX(0.001,('Operating Model'!$G$6*11-'Operating Model'!$G$21)/(('Sources & Uses'!$B$18/Assumptions!$B$8)*11.5*Assumptions!$B$6))^(1/Assumptions!$B$28)-1,"N/A") -> 0.19617459 | F30: =IF(MAX(0.001,('Operating Model'!$G$6*11-'Operating Model'!$G$21)/(('Sources & Uses'!$B$18/Assumptions!$B$8)*12*Assumptions!$B$6))>0,MAX(0.001,('Operating Model'!$G$6*11-'Operating Model'!$G$21)/(('Sources & Uses'!$B$18/Assumptions!$B$8)*12*Assumptions!$B$6))^(1/Assumptions!$B$28)-1,"N/A") -> 0.18603605 | G30: =IF(MAX(0.001,('Operating Model'!$G$6*11-'Operating Model'!$G$21)/(('Sources & Uses'!$B$18/Assumptions!$B$8)*12.5*Assumptions!$B$6))>0,MAX(0.001,('Operating Model'!$G$6*11-'Operating Model'!$G$21)/(('Sources & Uses'!$B$18/Assumptions!$B$8)*12.5*Assumptions!$B$6))^(1/Assumptions!$B$28)-1,"N/A") -> 0.17639221
A31: 12 | B31: =IF(MAX(0.001,('Operating Model'!$G$6*12-'Operating Model'!$G$21)/(('Sources & Uses'!$B$18/Assumptions!$B$8)*10*Assumptions!$B$6))>0,MAX(0.001,('Operating Model'!$G$6*12-'Operating Model'!$G$21)/(('Sources & Uses'!$B$18/Assumptions!$B$8)*10*Assumptions!$B$6))^(1/Assumptions!$B$28)-1,"N/A") -> 0.2553578 | C31: =IF(MAX(0.001,('Operating Model'!$G$6*12-'Operating Model'!$G$21)/(('Sources & Uses'!$B$18/Assumptions!$B$8)*10.5*Assumptions!$B$6))>0,MAX(0.001,('Operating Model'!$G$6*12-'Operating Model'!$G$21)/(('Sources & Uses'!$B$18/Assumptions!$B$8)*10.5*Assumptions!$B$6))^(1/Assumptions!$B$28)-1,"N/A") -> 0.24316755 | D31: =IF(MAX(0.001,('Operating Model'!$G$6*12-'Operating Model'!$G$21)/(('Sources & Uses'!$B$18/Assumptions!$B$8)*11*Assumptions!$B$6))>0,MAX(0.001,('Operating Model'!$G$6*12-'Operating Model'!$G$21)/(('Sources & Uses'!$B$18/Assumptions!$B$8)*11*Assumptions!$B$6))^(1/Assumptions!$B$28)-1,"N/A") -> 0.23165476 | E31: =IF(MAX(0.001,('Operating Model'!$G$6*12-'Operating Model'!$G$21)/(('Sources & Uses'!$B$18/Assumptions!$B$8)*11.5*Assumptions!$B$6))>0,MAX(0.001,('Operating Model'!$G$6*12-'Operating Model'!$G$21)/(('Sources & Uses'!$B$18/Assumptions!$B$8)*11.5*Assumptions!$B$6))^(1/Assumptions!$B$28)-1,"N/A") -> 0.22075344 | F31: =IF(MAX(0.001,('Operating Model'!$G$6*12-'Operating Model'!$G$21)/(('Sources & Uses'!$B$18/Assumptions!$B$8)*12*Assumptions!$B$6))>0,MAX(0.001,('Operating Model'!$G$6*12-'Operating Model'!$G$21)/(('Sources & Uses'!$B$18/Assumptions!$B$8)*12*Assumptions!$B$6))^(1/Assumptions!$B$28)-1,"N/A") -> 0.21040658 | G31: =IF(MAX(0.001,('Operating Model'!$G$6*12-'Operating Model'!$G$21)/(('Sources & Uses'!$B$18/Assumptions!$B$8)*12.5*Assumptions!$B$6))>0,MAX(0.001,('Operating Model'!$G$6*12-'Operating Model'!$G$21)/(('Sources & Uses'!$B$18/Assumptions!$B$8)*12.5*Assumptions!$B$6))^(1/Assumptions!$B$28)-1,"N/A") -> 0.20056457
A32: 13 | B32: =IF(MAX(0.001,('Operating Model'!$G$6*13-'Operating Model'!$G$21)/(('Sources & Uses'!$B$18/Assumptions!$B$8)*10*Assumptions!$B$6))>0,MAX(0.001,('Operating Model'!$G$6*13-'Operating Model'!$G$21)/(('Sources & Uses'!$B$18/Assumptions!$B$8)*10*Assumptions!$B$6))^(1/Assumptions!$B$28)-1,"N/A") -> 0.27874786 | C32: =IF(MAX(0.001,('Operating Model'!$G$6*13-'Operating Model'!$G$21)/(('Sources & Uses'!$B$18/Assumptions!$B$8)*10.5*Assumptions!$B$6))>0,MAX(0.001,('Operating Model'!$G$6*13-'Operating Model'!$G$21)/(('Sources & Uses'!$B$18/Assumptions!$B$8)*10.5*Assumptions!$B$6))^(1/Assumptions!$B$28)-1,"N/A") -> 0.26633048 | D32: =IF(MAX(0.001,('Operating Model'!$G$6*13-'Operating Model'!$G$21)/(('Sources & Uses'!$B$18/Assumptions!$B$8)*11*Assumptions!$B$6))>0,MAX(0.001,('Operating Model'!$G$6*13-'Operating Model'!$G$21)/(('Sources & Uses'!$B$18/Assumptions!$B$8)*11*Assumptions!$B$6))^(1/Assumptions!$B$28)-1,"N/A") -> 0.25460317 | E32: =IF(MAX(0.001,('Operating Model'!$G$6*13-'Operating Model'!$G$21)/(('Sources & Uses'!$B$18/Assumptions!$B$8)*11.5*Assumptions!$B$6))>0,MAX(0.001,('Operating Model'!$G$6*13-'Operating Model'!$G$21)/(('Sources & Uses'!$B$18/Assumptions!$B$8)*11.5*Assumptions!$B$6))^(1/Assumptions!$B$28)-1,"N/A") -> 0.24349874 | F32: =IF(MAX(0.001,('Operating Model'!$G$6*13-'Operating Model'!$G$21)/(('Sources & Uses'!$B$18/Assumptions!$B$8)*12*Assumptions!$B$6))>0,MAX(0.001,('Operating Model'!$G$6*13-'Operating Model'!$G$21)/(('Sources & Uses'!$B$18/Assumptions!$B$8)*12*Assumptions!$B$6))^(1/Assumptions!$B$28)-1,"N/A") -> 0.2329591 | G32: =IF(MAX(0.001,('Operating Model'!$G$6*13-'Operating Model'!$G$21)/(('Sources & Uses'!$B$18/Assumptions!$B$8)*12.5*Assumptions!$B$6))>0,MAX(0.001,('Operating Model'!$G$6*13-'Operating Model'!$G$21)/(('Sources & Uses'!$B$18/Assumptions!$B$8)*12.5*Assumptions!$B$6))^(1/Assumptions!$B$28)-1,"N/A") -> 0.22293371
A33: 14 | B33: =IF(MAX(0.001,('Operating Model'!$G$6*14-'Operating Model'!$G$21)/(('Sources & Uses'!$B$18/Assumptions!$B$8)*10*Assumptions!$B$6))>0,MAX(0.001,('Operating Model'!$G$6*14-'Operating Model'!$G$21)/(('Sources & Uses'!$B$18/Assumptions!$B$8)*10*Assumptions!$B$6))^(1/Assumptions!$B$28)-1,"N/A") -> 0.30054208 | C33: =IF(MAX(0.001,('Operating Model'!$G$6*14-'Operating Model'!$G$21)/(('Sources & Uses'!$B$18/Assumptions!$B$8)*10.5*Assumptions!$B$6))>0,MAX(0.001,('Operating Model'!$G$6*14-'Operating Model'!$G$21)/(('Sources & Uses'!$B$18/Assumptions!$B$8)*10.5*Assumptions!$B$6))^(1/Assumptions!$B$28)-1,"N/A") -> 0.28791307 | D33: =IF(MAX(0.001,('Operating Model'!$G$6*14-'Operating Model'!$G$21)/(('Sources & Uses'!$B$18/Assumptions!$B$8)*11*Assumptions!$B$6))>0,MAX(0.001,('Operating Model'!$G$6*14-'Operating Model'!$G$21)/(('Sources & Uses'!$B$18/Assumptions!$B$8)*11*Assumptions!$B$6))^(1/Assumptions!$B$28)-1,"N/A") -> 0.27598589 | E33: =IF(MAX(0.001,('Operating Model'!$G$6*14-'Operating Model'!$G$21)/(('Sources & Uses'!$B$18/Assumptions!$B$8)*11.5*Assumptions!$B$6))>0,MAX(0.001,('Operating Model'!$G$6*14-'Operating Model'!$G$21)/(('Sources & Uses'!$B$18/Assumptions!$B$8)*11.5*Assumptions!$B$6))^(1/Assumptions!$B$28)-1,"N/A") -> 0.26469221 | F33: =IF(MAX(0.001,('Operating Model'!$G$6*14-'Operating Model'!$G$21)/(('Sources & Uses'!$B$18/Assumptions!$B$8)*12*Assumptions!$B$6))>0,MAX(0.001,('Operating Model'!$G$6*14-'Operating Model'!$G$21)/(('Sources & Uses'!$B$18/Assumptions!$B$8)*12*Assumptions!$B$6))^(1/Assumptions!$B$28)-1,"N/A") -> 0.25397293 | G33: =IF(MAX(0.001,('Operating Model'!$G$6*14-'Operating Model'!$G$21)/(('Sources & Uses'!$B$18/Assumptions!$B$8)*12.5*Assumptions!$B$6))>0,MAX(0.001,('Operating Model'!$G$6*14-'Operating Model'!$G$21)/(('Sources & Uses'!$B$18/Assumptions!$B$8)*12.5*Assumptions!$B$6))^(1/Assumptions!$B$28)-1,"N/A") -> 0.24377667
A35: Yellow = Base Case (Entry 11.5x, Exit 12.0x, 5-year hold)
